Workbook

Sheet PARCELAMENTOS
A1: ITEM | B1: ATIVOS E BENS | C1: Detalhes | D1: FORMATO | E1: TIPO | F1: EMPRESA | G1: Documento | H1: CENTRO DE CUSTO | I1: STATUS | J1: FORMA DE PAGTO | K1: Dia Débito | L1: Início Contrato | M1: Término Contrato | N1: Mês | O1: Total Contrato | P1: Parcelas Contratadas | Q1: Valor Parcela | R1: Parcelas Pagas | S1: Parcelas Restantes | T1: Total Pago | U1: Montante a Pagar
A2: 1 | B2: Trator | D2: FINANCIAMENTO | E2: ATIVOS | F2: MAR BRASIL | G2: Contr 014799729 | H2: NOSSA EMPRESA | I2: Pagando | J2: Débito CC Bradesco - MBR | K2: 19 | L2: 44366 | M2: 46192 | N2: =M2 -> 46192 | O2: 321796.8 | P2: 60 | Q2: 5363.3 | R2: 54 | S2: =P2-R2 -> 6 | T2: =R2*Q2 -> 289618.2 | U2: =Tabela2[[#This Row],[Parcelas Restantes]]*Tabela2[[#This Row],[Valor Parcela]] -> 32179.8
A3: 2 | B3: Plataforma GL-12 | D3: FINANCIAMENTO | E3: ATIVOS | F3: CONECTIUS | H3: Conectius - Rateio | I3: Pagando | J3: BNDES Bradesco - CONECTIUS | K3: 15 | L3: 44849 | M3: 45915 | N3: =M3 -> 45915 | O3: =Q3*P3 -> 60549.48 | P3: 36 | Q3: 1681.93 | R3: 36 | S3: =P3-R3 -> 0 | T3: =R3*Q3 -> 60549.48 | U3: =Tabela2[[#This Row],[Parcelas Restantes]]*Tabela2[[#This Row],[Valor Parcela]] -> 0
A4: 3 | B4: ABC Telhas Metálicas | C4: Material ribeirópolis | D4: FINANCIAMENTO | E4: ATIVOS | F4: MAR BRASIL | H4: Mar Brasil - Rateio | I4: Pagando | J4: BNDES Bradesco - Mar Brasil | K4: 15 | L4: 45098 | M4: 46310 | O4: 79039.6 | P4: 40 | Q4: 1975.99 | R4: 29 | S4: =P4-R4 -> 11 | T4: =R4*Q4 -> 57303.71 | U4: =Tabela2[[#This Row],[Parcelas Restantes]]*Tabela2[[#This Row],[Valor Parcela]] -> 21735.89
A5: 4 | B5: Caminhão GL-12 | C5: CDC Veículo | D5: FINANCIAMENTO | E5: ATIVOS | F5: CONECTIUS | G5: Contr 5897374 | H5: Conectius - Rateio | I5: Transferido | J5: Débito CC Bradesco - CONECTIUS | K5: 28 | L5: 44802 | M5: 46597 | N5: =M5 -> 46597 | O5: =Q5*P5 -> 337354.8 | P5: 60 | Q5: 5622.58 | R5: 40 | S5: =P5-R5 -> 20 | T5: =R5*Q5 -> 224903.2 | U5: =Tabela2[[#This Row],[Parcelas Restantes]]*Tabela2[[#This Row],[Valor Parcela]] -> 112451.6
A6: 5 | B6: New Comercio | D6: FINANCIAMENTO | E6: ATIVOS | F6: CONECTIUS | H6: Conectius - Rateio | I6: Pagando | J6: BNDES Bradesco - CONECTIUS | K6: 15 | L6: 45153 | M6: 46218 | O6: 29255.4 | P6: 36 | Q6: 812.65 | R6: 24 | S6: 12 | T6: =R6*Q6 -> 19503.6 | U6: =Tabela2[[#This Row],[Parcelas Restantes]]*Tabela2[[#This Row],[Valor Parcela]] -> 9751.8
A7: 6 | B7: LOTE 6 - Casa Dauren Pri | D7: FINANCIAMENTO | E7: ATIVOS | F7: PESSOAL | H7: PESSOAL | I7: Pagando | J7: VIA PIX ITAÚ PRI PF | K7: 20 | L7: 44991 | M7: 46863 | N7: =M7 -> 46863 | O7: 650000 | P7: 66 | Q7: 5000 | R7: 36 | S7: =P7-R7 -> 30 | T7: 460000 | U7: =Tabela2[[#This Row],[Parcelas Restantes]]*Tabela2[[#This Row],[Valor Parcela]] -> 150000
A8: 7 | B8: Carro SONGPLUS BYD | D8: FINANCIAMENTO | E8: ATIVOS | F8: MAR BRASIL | G8: Contr 291482031 | H8: Mar Brasil - Rateio | I8: Pagando | J8: Débito CC Bradesco - MBR | K8: 3 | L8: 45258 | M8: 46731 | N8: =M8 -> 46731 | O8: 225465.66 | P8: 48 | Q8: 4601.34 | R8: 24 | S8: =P8-R8 -> 24 | T8: =Q8*R8+79800 -> 190232.16 | U8: =Tabela2[[#This Row],[Parcelas Restantes]]*Tabela2[[#This Row],[Valor Parcela]] -> 110432.16
A9: 8 | B9: Caminhonete Iveco | D9: FINANCIAMENTO | E9: ATIVOS | F9: MAR BRASIL | H9: Mar Brasil - Rateio | I9: =IF(S9>0,"Pagando","Liquidado") -> Liquidado | K9: 19 | L9: 45310 | M9: 45622 | O9: 129196.44 | P9: 12 | Q9: 3588.79 | R9: 12 | S9: =P9-R9 -> 0 | T9: 113907.48 | U9: =Tabela2[[#This Row],[Parcelas Restantes]]*Tabela2[[#This Row],[Valor Parcela]] -> 0
A10: 9 | B10: Consórcio Bradesco | C10: Grupo 10447 cota 54 | D10: CONSÓRCIO | E10: ATIVOS | F10: CONECTIUS | G10: Contr 701664330 | H10: Conectius - Rateio | I10: Pagando | J10: Débito CC Bradesco | K10: 10 | L10: 44770 | M10: 47480 | N10: =M10 -> 47480 | O10: =Q10*P10 -> 63233.61 | P10: 89 | Q10: 710.49 | R10: 39 | S10: =P10-R10 -> 50 | T10: 22575.9 | U10: =Tabela2[[#This Row],[Parcelas Restantes]]*Tabela2[[#This Row],[Valor Parcela]] -> 35524.5
A11: 10 | B11: Consórcio Bradesco | C11: Grupo 10010 cota 167 | D11: CONSÓRCIO | E11: ATIVOS | F11: CONECTIUS | H11: Conectius - Rateio | I11: Desistido | J11: Débito CC Bradesco | K11: 10 | L11: 45016 | M11: 45148 | O11: 40914 | P11: 65 | Q11: 750.17 | R11: 5 | S11: 0 | T11: =Consórcios!D4 -> 3812.01 | U11: =Tabela2[[#This Row],[Parcelas Restantes]]*Tabela2[[#This Row],[Valor Parcela]] -> 0
A12: 11 | B12: Consórcio Bradesco | C12: Grupo 10051 cota 186 | D12: CONSÓRCIO | E12: ATIVOS | F12: CONECTIUS | H12: Conectius - Rateio | I12: Desistido | J12: Débito CC Bradesco | K12: 10 | L12: 45016 | M12: 45148 | O12: 40914 | P12: 66 | Q12: 741.45 | R12: 5 | S12: 0 | T12: =Consórcios!D5 -> 3754.47 | U12: =Tabela2[[#This Row],[Parcelas Restantes]]*Tabela2[[#This Row],[Valor Parcela]] -> 0
A13: 12 | B13: Consórcio Bradesco | C13: Grupo 10069 cota 175 | D13: CONSÓRCIO | E13: ATIVOS | F13: CONECTIUS | H13: Conectius - Rateio | I13: Desistido | J13: Débito CC Bradesco | K13: 10 | L13: 45016 | M13: 45148 | O13: 40914 | P13: 66 | Q13: 741.45 | R13: 5 | S13: 0 | T13: =Consórcios!D6 -> 3754.47 | U13: =Tabela2[[#This Row],[Parcelas Restantes]]*Tabela2[[#This Row],[Valor Parcela]] -> 0
A14: 13 | B14: Consórcio Massey | C14: Grupo 0366 cota 0804 | D14: CONSÓRCIO | E14: ATIVOS | F14: MAR BRASIL | G14: Contemplado | H14: Mar Brasil - Rateio | I14: =IF(S14>0,"Pagando","Liquidado") -> Pagando | J14: Boleto - Tchandra | K14: 20 | L14: 45379 | M14: 47177 | N14: =M14 -> 47177 | O14: 191982 | P14: 60 | Q14: 2464.47 | R14: 19 | S14: =P14-R14 -> 41 | T14: =Consórcios!B7 -> 79635.02 | U14: =Tabela2[[#This Row],[Parcelas Restantes]]*Tabela2[[#This Row],[Valor Parcela]] -> 101043.27
A15: 14 | B15: Consórcio Massey | C15: Grupo 0378 cota 0458 | D15: CONSÓRCIO | E15: ATIVOS | F15: MAR BRASIL | H15: Mar Brasil - Rateio | I15: =IF(S15>0,"Pagando","Liquidado") -> Pagando | J15: Débito CC Bradesco | K15: 20 | L15: 45379 | M15: 48901 | N15: =M15 -> 48901 | O15: =Q15*P15 -> 332315.1 | P15: 117 | Q15: 2840.3 | R15: 21 | S15: =P15-R15 -> 96 | T15: =Q15*R15 -> 59646.3 | U15: =Tabela2[[#This Row],[Parcelas Restantes]]*Tabela2[[#This Row],[Valor Parcela]] -> 272668.8
A16: 15 | B16: Consórcio Massey | C16: Grupo 0367 cota 0202 | D16: CONSÓRCIO | E16: ATIVOS | F16: MAR BRASIL | G16: Contemplado | H16: Mar Brasil - Rateio | I16: =IF(S16>0,"Pagando","Liquidado") -> Pagando | J16: Débito CC Bradesco | K16: 20 | L16: 45379 | M16: 47177 | N16: =M16 -> 47177 | O16: 193396 | P16: 60 | Q16: 2412.72 | R16: 21 | S16: =P16-R16 -> 39 | T16: =Consórcios!B8 -> 80221.58 | U16: =Tabela2[[#This Row],[Parcelas Restantes]]*Tabela2[[#This Row],[Valor Parcela]] -> 94096.08
A17: 16 | B17: Compra Notebook | D17: PARCELAMENTO | E17: ATIVOS | F17: MAR BRASIL | H17: Mar Brasil - Rateio | I17: Liquidado | J17: CC Elo - Priscilla | K17: 10 | L17: 45545 | M17: 45818 | O17: =Q17*P17 -> 3199 | P17: 10 | Q17: 319.9 | R17: 10 | S17: =P17-R17 -> 0 | T17: =Q17*R17 -> 3199 | U17: =Tabela2[[#This Row],[Parcelas Restantes]]*Tabela2[[#This Row],[Valor Parcela]] -> 0
A18: 17 | B18: Compra Notebook | D18: PARCELAMENTO | E18: ATIVOS | F18: MAR BRASIL | H18: Mar Brasil - Rateio | I18: Liquidado | J18: CC Elo - Priscilla | K18: 10 | L18: 45545 | M18: 45818 | O18: =Q18*P18 -> 3199 | P18: 10 | Q18: 319.9 | R18: 10 | S18: =P18-R18 -> 0 | T18: =Q18*R18 -> 3199 | U18: =Tabela2[[#This Row],[Parcelas Restantes]]*Tabela2[[#This Row],[Valor Parcela]] -> 0
A19: 18 | B19: Compra Notebook | C19: - 4un | D19: PARCELAMENTO | E19: ATIVOS | F19: MAR BRASIL | H19: Mar Brasil - Rateio | I19: =IF(S19>0,"Pagando","Liquidado") -> Liquidado | J19: CC Sicredi Visa Empresarial | K19: 23 | L19: 45586 | M19: 45859 | N19: =M19 -> 45859 | O19: =Q19*P19 -> 11196 | P19: 10 | Q19: 1119.6 | R19: 10 | S19: =P19-R19 -> 0 | T19: =Q19*R19 -> 11196 | U19: =Tabela2[[#This Row],[Parcelas Restantes]]*Tabela2[[#This Row],[Valor Parcela]] -> 0
A20: 19 | B20: Compra Notebooks | C20: - 7un | D20: PARCELAMENTO | E20: ATIVOS | F20: MAR BRASIL | H20: Mar Brasil - Rateio | I20: =IF(S20>0,"Pagando","Liquidado") -> Pagando | J20: CC Elo - Dauren | K20: 10 | L20: 45787 | M20: 46032 | N20: =M20 -> 46032 | O20: 28050.52 | P20: 12 | Q20: 2337.54 | R20: 8 | S20: =P20-R20 -> 4 | T20: =Q20*R20 -> 18700.32 | U20: =Tabela2[[#This Row],[Parcelas Restantes]]*Tabela2[[#This Row],[Valor Parcela]] -> 9350.16
A21: 20 | B21: Compra Monitores | C21: - 10un | D21: PARCELAMENTO | E21: ATIVOS | F21: MAR BRASIL | H21: Mar Brasil - Rateio | I21: =IF(S21>0,"Pagando","Liquidado") -> Pagando | J21: CC Elo - Priscilla | K21: 10 | L21: 45755 | M21: 46032 | N21: =M21 -> 46032 | O21: 5390 | P21: 10 | Q21: 539 | R21: 9 | S21: =P21-R21 -> 1 | T21: =Q21*R21 -> 4851 | U21: =Tabela2[[#This Row],[Parcelas Restantes]]*Tabela2[[#This Row],[Valor Parcela]] -> 539
A22: 21 | B22: Compra Monitores | C22: - 10un | D22: PARCELAMENTO | E22: ATIVOS | F22: MAR BRASIL | H22: Mar Brasil - Rateio | I22: =IF(S22>0,"Pagando","Liquidado") -> Pagando | J22: CC Elo - Dauren | K22: 10 | L22: 45787 | M22: 46032 | N22: =M22 -> 46032 | O22: 6520 | P22: 10 | Q22: 652 | R22: 8 | S22: =P22-R22 -> 2 | T22: =Q22*R22 -> 5216 | U22: =Tabela2[[#This Row],[Parcelas Restantes]]*Tabela2[[#This Row],[Valor Parcela]] -> 1304
A23: 22 | B23: Compra Monitor | C23: Priscilla/Tchandra | D23: PARCELAMENTO | E23: ATIVOS | F23: MAR BRASIL | H23: Mar Brasil - Rateio | I23: =IF(S23>0,"Pagando","Liquidado") -> Liquidado | J23: CC Sicredi Visa Empresarial | K23: 23 | L23: 45464 | M23: 45798 | O23: =Q23*P23 -> 2098.2 | P23: 12 | Q23: 174.85 | R23: 12 | S23: =P23-R23 -> 0 | T23: =Q23*R23 -> 2098.2 | U23: =Tabela2[[#This Row],[Parcelas Restantes]]*Tabela2[[#This Row],[Valor Parcela]] -> 0
A24: 23 | B24: Smartphones | C24: - 05un | D24: PARCELAMENTO | E24: ATIVOS | F24: MAR BRASIL | H24: Mar Brasil - Rateio | I24: =IF(S24>0,"Pagando","Liquidado") -> Liquidado | J24: CC Elo - Priscilla | K24: 10 | L24: 45301 | M24: 45575 | O24: 5834 | P24: 10 | Q24: 583.4 | R24: 10 | S24: =P24-R24 -> 0 | T24: =R24*Q24 -> 5834 | U24: =Tabela2[[#This Row],[Parcelas Restantes]]*Tabela2[[#This Row],[Valor Parcela]] -> 0
A25: 24 | B25: Smartphones | C25: - 04un | D25: PARCELAMENTO | E25: ATIVOS | F25: MAR BRASIL | H25: Mar Brasil - Rateio | I25: =IF(S25>0,"Pagando","Liquidado") -> Liquidado | J25: CC Elo - Priscilla | K25: 10 | L25: 45575 | M25: 45879 | N25: =M25 -> 45879 | O25: 5803.4 | P25: 10 | Q25: 580.34 | R25: 10 | S25: =P25-R25 -> 0 | T25: =R25*Q25 -> 5803.4 | U25: =Tabela2[[#This Row],[Parcelas Restantes]]*Tabela2[[#This Row],[Valor Parcela]] -> 0
A26: 25 | B26: Smartphones | C26: - 02un | D26: PARCELAMENTO | E26: ATIVOS | F26: MAR BRASIL | H26: Mar Brasil - Rateio | I26: =IF(S26>0,"Pagando","Liquidado") -> Liquidado | J26: CC Elo - Priscilla | K26: 10 | L26: 45545 | M26: 45818 | O26: 3295.8 | P26: 10 | Q26: 329.58 | R26: 10 | S26: =P26-R26 -> 0 | T26: =R26*Q26 -> 3295.8 | U26: =Tabela2[[#This Row],[Parcelas Restantes]]*Tabela2[[#This Row],[Valor Parcela]] -> 0
A27: 26 | B27: Iphone | C27: - Priscilla | D27: PARCELAMENTO | E27: ATIVOS | F27: MAR BRASIL | H27: Mar Brasil - Rateio | I27: =IF(S27>0,"Pagando","Liquidado") -> Pagando | J27: Fatura Claro | K27: 10 | L27: 45989 | M27: 46688 | N27: =M27 -> 46688 | O27: 8930 | P27: 24 | Q27: 247.46 | R27: 0 | S27: =P27-R27 -> 24 | T27: =R27*Q27 -> 0 | U27: =Tabela2[[#This Row],[Parcelas Restantes]]*Tabela2[[#This Row],[Valor Parcela]] -> 5939.04
A28: 26 | B28: Iphone | C28: - Priscilla | D28: PARCELAMENTO | E28: ATIVOS | F28: MAR BRASIL | H28: Mar Brasil - Rateio | I28: =IF(S28>0,"Pagando","Liquidado") -> Pagando | K28: 10 | L28: 45270 | M28: 46001 | N28: =M28 -> 46001 | O28: 5939.04 | P28: 24 | Q28: 247.46 | R28: 23 | S28: =P28-R28 -> 1 | T28: =R28*Q28 -> 5691.58 | U28: =Tabela2[[#This Row],[Parcelas Restantes]]*Tabela2[[#This Row],[Valor Parcela]] -> 247.46
A29: 27 | B29: Cadeiras Escritório | C29: Comercial | D29: PARCELAMENTO | E29: ATIVOS | F29: MAR BRASIL | H29: Mar Brasil - Rateio | I29: =IF(S29>0,"Pagando","Liquidado") -> Liquidado | J29: CC Elo - Priscilla | K29: 10 | L29: 45667 | M29: 45940 | N29: =M29 -> 45940 | O29: =Q29*P29 -> 4428.8 | P29: 10 | Q29: 442.88 | R29: 10 | S29: =P29-R29 -> 0 | T29: =Q29*R29 -> 4428.8 | U29: =Tabela2[[#This Row],[Parcelas Restantes]]*Tabela2[[#This Row],[Valor Parcela]] -> 0
A30: 28 | B30: Cadeiras Escritório | C30: TI | D30: PARCELAMENTO | E30: ATIVOS | F30: MAR BRASIL | H30: Mar Brasil - Rateio | I30: =IF(S30>0,"Pagando","Liquidado") -> Liquidado | J30: CC Elo - Priscilla | K30: 10 | L30: 45698 | M30: 45971 | N30: =M30 -> 45971 | O30: =Q30*P30 -> 3338.1 | P30: 10 | Q30: 333.81 | R30: 10 | S30: =P30-R30 -> 0 | T30: =Q30*R30 -> 3338.1 | U30: =Tabela2[[#This Row],[Parcelas Restantes]]*Tabela2[[#This Row],[Valor Parcela]] -> 0
A31: 29 | B31: Televisores Escritório | C31: 03 unidades | D31: PARCELAMENTO | E31: ATIVOS | F31: MAR BRASIL | H31: Mar Brasil - Rateio | I31: =IF(S31>0,"Pagando","Liquidado") -> Liquidado | J31: CC Sicredi Visa Empresarial | K31: 23 | L31: 45558 | M31: 45890 | N31: =M31 -> 45890 | O31: =Q31*P31 -> 7797 | P31: 12 | Q31: 649.75 | R31: 12 | S31: =P31-R31 -> 0 | T31: =Q31*R31 -> 7797 | U31: =Tabela2[[#This Row],[Parcelas Restantes]]*Tabela2[[#This Row],[Valor Parcela]] -> 0
A32: 30 | B32: Compra Tenda | D32: PARCELAMENTO | E32: ATIVOS | F32: MAR BRASIL | H32: Mar Brasil - Rancho | I32: =IF(S32>0,"Pagando","Liquidado") -> Liquidado | J32: CC Sicredi Visa Empresarial | K32: 23 | L32: 45529 | M32: 45863 | N32: =M32 -> 45863 | O32: =Q32*P32 -> 9087 | P32: 12 | Q32: 757.25 | R32: 12 | S32: =P32-R32 -> 0 | T32: =Q32*R32 -> 9087 | U32: =Tabela2[[#This Row],[Parcelas Restantes]]*Tabela2[[#This Row],[Valor Parcela]] -> 0
A33: 31 | B33: Compra Roçadeira | D33: PARCELAMENTO | E33: ATIVOS | F33: MAR BRASIL | H33: DZM - Rancho | I33: =IF(S33>0,"Pagando","Liquidado") -> Liquidado | J33: CC Sicredi Visa Empresarial | K33: 23 | L33: 45680 | M33: 45984 | N33: =M33 -> 45984 | O33: =Q33*P33 -> 693.9 | P33: 10 | Q33: 69.39 | R33: 10 | S33: =P33-R33 -> 0 | T33: =Q33*R33 -> 693.9 | U33: =Tabela2[[#This Row],[Parcelas Restantes]]*Tabela2[[#This Row],[Valor Parcela]] -> 0
A34: 32 | B34: Parcelamento Alvará 2025 | D34: PARCELAMENTO | E34: DESPESA | F34: MAR BRASIL | H34: Mar Brasil - Rateio | I34: =IF(S34>0,"Pagando","Liquidado") -> Liquidado | J34: Guia | K34: 9 | L34: 45667 | M34: 45879 | N34: =M34 -> 45879 | O34: 2322.5 | P34: 8 | Q34: 232.25 | R34: 8 | S34: =P34-R34 -> 0 | T34: =Q34*R34 -> 1858 | U34: =Tabela2[[#This Row],[Parcelas Restantes]]*Tabela2[[#This Row],[Valor Parcela]] -> 0
A35: 33 | B35: Parcelamento ISS 2022 | D35: PARCELAMENTO | E35: DESPESA | F35: MAR BRASIL | G35: 910009/2022 | H35: Mar Brasil - Rateio | I35: =IF(S35>0,"Pagando","Liquidado") -> Pagando | J35: Guia | K35: 11 | L35: 44662 | M35: 46457 | N35: =M35 -> 46457 | O35: =Q35*P35 -> 22198.2 | P35: 60 | Q35: 369.97 | R35: 44 | S35: =P35-R35 -> 16 | T35: =Q35*R35 -> 16278.68 | U35: =Tabela2[[#This Row],[Parcelas Restantes]]*Tabela2[[#This Row],[Valor Parcela]] -> 5919.52
A36: 34 | B36: Parcelamento Alvará 2020 | D36: PARCELAMENTO | E36: DESPESA | F36: MAR BRASIL | H36: Mar Brasil - Rateio | I36: =IF(S36>0,"Pagando","Liquidado") -> Liquidado | J36: Guia | K36: 25 | L36: 45071 | M36: 45404 | O36: 9307.15 | P36: 12 | Q36: 775.55 | R36: 12 | S36: =P36-R36 -> 0 | T36: =Q36*R36 -> 9306.6 | U36: =Tabela2[[#This Row],[Parcelas Restantes]]*Tabela2[[#This Row],[Valor Parcela]] -> 0
A37: 35 | B37: Parcelamento Simples Nacional | D37: PARCELAMENTO | E37: DESPESA | F37: MAR BRASIL | G37: Negociação 4911852 | H37: Mar Brasil - Rateio | I37: =IF(S37>0,"Pagando","Liquidado") -> Pagando | J37: Guia | K37: 28 | L37: 44469 | M37: 48852 | N37: =M37 -> 48852 | O37: 232082.29 | P37: 145 | Q37: 2294.22 | R37: 50 | S37: =P37-R37 -> 95 | T37: ='DAS Parc'!E2 -> 80788.61 | U37: =Tabela2[[#This Row],[Parcelas Restantes]]*Tabela2[[#This Row],[Valor Parcela]] -> 217950.9
A38: 36 | B38: Giro Pronampe | D38: PARCELAMENTO | E38: DESPESA | F38: MAR BRASIL | G38: Contr 015828170 | H38: Mar Brasil - Rateio | I38: =IF(S38>0,"Pagando","Liquidado") -> Pagando | J38: Débito CC Bradesco - MBR | K38: 27 | L38: 44797 | M38: 46261 | N38: =M38 -> 46261 | O38: 214605.19 | P38: 42 | Q38: 5815.27 | R38: 33 | S38: =P38-R38 -> 9 | T38: 112714.5 | U38: =Tabela2[[#This Row],[Parcelas Restantes]]*Tabela2[[#This Row],[Valor Parcela]] -> 52337.43
A39: 37 | B39: Giro Pronampe | D39: PARCELAMENTO | E39: DESPESA | F39: CONECTIUS | H39: Conectius - Rateio | I39: =IF(S39>0,"Pagando","Liquidado") -> Pagando | J39: Débito CC Itau - Conectius | K39: 30 | L39: 45015 | M39: 46264 | N39: =M39 -> 46264 | O39: 171116.4 | P39: 42 | Q39: 4081.99 | R39: 33 | S39: =P39-R39 -> 9 | T39: 140330.87 | U39: =Tabela2[[#This Row],[Parcelas Restantes]]*Tabela2[[#This Row],[Valor Parcela]] -> 36737.91
A40: 38 | B40: Trabalhista (Ed Carlos) | D40: PARCELAMENTO | E40: DESPESA | F40: MAR BRASIL | H40: Mar Brasil - Rateio | I40: =IF(S40>0,"Pagando","Liquidado") -> Pagando | K40: 13 | L40: 45670 | M40: 46094 | N40: =M40 -> 46094 | O40: 12000 | P40: 16 | Q40: 750 | R40: 5 | S40: =P40-R40 -> 11 | T40: =R40*Q40 -> 3750 | U40: =Tabela2[[#This Row],[Parcelas Restantes]]*Tabela2[[#This Row],[Valor Parcela]] -> 8250
...

Sheet Parcelas

Sheet Montantes

Sheet Projeção
A1: Ano | B1: Total | C1: Janeiro | D1: Fevereiro | E1: Março | F1: Abril | G1: Maio | H1: Junho | I1: Julho | J1: Agosto | K1: Setembro | L1: Outubro | M1: Novembro | N1: Dezembro
A2: 2025 | B2: =SUM(C2:N2) -> 605039.36 | C2: =SUMIF(PARCELAMENTOS!$N:$N,">30/12/2024",PARCELAMENTOS!$Q:$Q) -> 52217.31 | D2: =SUMIF(PARCELAMENTOS!$N:$N,">31/01/2025",PARCELAMENTOS!$Q:$Q) -> 52217.31 | E2: =SUMIF(PARCELAMENTOS!$N:$N,">28/02/2025",PARCELAMENTOS!$Q:$Q) -> 52217.31 | F2: =SUMIF(PARCELAMENTOS!$N:$N,">31/03/2025",PARCELAMENTOS!$Q:$Q) -> 52217.31 | G2: =SUMIF(PARCELAMENTOS!$N:$N,">30/04/2025",PARCELAMENTOS!$Q:$Q) -> 52217.31 | H2: =SUMIF(PARCELAMENTOS!$N:$N,">31/05/2025",PARCELAMENTOS!$Q:$Q) -> 52217.31 | I2: =SUMIF(PARCELAMENTOS!$N:$N,">30/06/2025",PARCELAMENTOS!$Q:$Q) -> 52217.31 | J2: =SUMIF(PARCELAMENTOS!$N:$N,">30/07/2025",PARCELAMENTOS!$Q:$Q) -> 50340.46 | K2: =SUMIF(PARCELAMENTOS!$N:$N,">30/08/2025",PARCELAMENTOS!$Q:$Q) -> 48878.12 | L2: =SUMIF(PARCELAMENTOS!$N:$N,">30/09/2025",PARCELAMENTOS!$Q:$Q) -> 47196.19 | M2: =SUMIF(PARCELAMENTOS!$N:$N,">30/10/2025",PARCELAMENTOS!$Q:$Q) -> 46753.31 | N2: =SUMIF(PARCELAMENTOS!$N:$N,">30/11/2025",PARCELAMENTOS!$Q:$Q) -> 46350.11
A3: 2026 | B3: =SUM(C3:N3) -> 435899.02 | C3: =SUMIF(PARCELAMENTOS!$N:$N,">30/12/2025",PARCELAMENTOS!$Q:$Q) -> 46102.65 | D3: =SUMIF(PARCELAMENTOS!$N:$N,">31/01/2026",PARCELAMENTOS!$Q:$Q) -> 42574.11 | E3: =SUMIF(PARCELAMENTOS!$N:$N,">28/02/2026",PARCELAMENTOS!$Q:$Q) -> 42574.11 | F3: =SUMIF(PARCELAMENTOS!$N:$N,">31/03/2026",PARCELAMENTOS!$Q:$Q) -> 41824.11 | G3: =SUMIF(PARCELAMENTOS!$N:$N,">30/04/2026",PARCELAMENTOS!$Q:$Q) -> 41824.11 | H3: =SUMIF(PARCELAMENTOS!$N:$N,">31/05/2026",PARCELAMENTOS!$Q:$Q) -> 41824.11 | I3: =SUMIF(PARCELAMENTOS!$N:$N,">30/06/2026",PARCELAMENTOS!$Q:$Q) -> 36460.81 | J3: =SUMIF(PARCELAMENTOS!$N:$N,">31/07/2026",PARCELAMENTOS!$Q:$Q) -> 36460.81 | K3: =SUMIF(PARCELAMENTOS!$N:$N,">31/08/2026",PARCELAMENTOS!$Q:$Q) -> 26563.55 | L3: =SUMIF(PARCELAMENTOS!$N:$N,">30/09/2026",PARCELAMENTOS!$Q:$Q) -> 26563.55 | M3: =SUMIF(PARCELAMENTOS!$N:$N,">31/10/2026",PARCELAMENTOS!$Q:$Q) -> 26563.55 | N3: =SUMIF(PARCELAMENTOS!$N:$N,">30/11/2026",PARCELAMENTOS!$Q:$Q) -> 26563.55
A4: 2027 | B4: =SUM(C4:N4) -> 286825.05 | C4: =SUMIF(PARCELAMENTOS!$N:$N,">30/12/2026",PARCELAMENTOS!$Q:$Q) -> 26563.55 | D4: =SUMIF(PARCELAMENTOS!$N:$N,">31/01/2027",PARCELAMENTOS!$Q:$Q) -> 26563.55 | E4: =SUMIF(PARCELAMENTOS!$N:$N,">28/02/2027",PARCELAMENTOS!$Q:$Q) -> 26563.55 | F4: =SUMIF(PARCELAMENTOS!$N:$N,">31/03/2027",PARCELAMENTOS!$Q:$Q) -> 26193.58 | G4: =SUMIF(PARCELAMENTOS!$N:$N,">30/04/2027",PARCELAMENTOS!$Q:$Q) -> 26193.58 | H4: =SUMIF(PARCELAMENTOS!$N:$N,">31/05/2027",PARCELAMENTOS!$Q:$Q) -> 26193.58 | I4: =SUMIF(PARCELAMENTOS!$N:$N,">30/06/2027",PARCELAMENTOS!$Q:$Q) -> 26193.58 | J4: =SUMIF(PARCELAMENTOS!$N:$N,">31/07/2027",PARCELAMENTOS!$Q:$Q) -> 20571 | K4: =SUMIF(PARCELAMENTOS!$N:$N,">31/08/2027",PARCELAMENTOS!$Q:$Q) -> 20571 | L4: =SUMIF(PARCELAMENTOS!$N:$N,">30/09/2027",PARCELAMENTOS!$Q:$Q) -> 20571 | M4: =SUMIF(PARCELAMENTOS!$N:$N,">31/10/2027",PARCELAMENTOS!$Q:$Q) -> 20323.54 | N4: =SUMIF(PARCELAMENTOS!$N:$N,">30/11/2027",PARCELAMENTOS!$Q:$Q) -> 20323.54
A5: 2028 | B5: =SUM(C5:N5) -> 148666.4 | C5: =SUMIF(PARCELAMENTOS!$N:$N,">30/12/2027",PARCELAMENTOS!$Q:$Q) -> 15722.2 | D5: =SUMIF(PARCELAMENTOS!$N:$N,">31/01/2028",PARCELAMENTOS!$Q:$Q) -> 15722.2 | E5: =SUMIF(PARCELAMENTOS!$N:$N,">28/02/2028",PARCELAMENTOS!$Q:$Q) -> 15722.2 | F5: =SUMIF(PARCELAMENTOS!$N:$N,">31/03/2028",PARCELAMENTOS!$Q:$Q) -> 15722.2 | G5: =SUMIF(PARCELAMENTOS!$N:$N,">30/04/2028",PARCELAMENTOS!$Q:$Q) -> 10722.2 | H5: =SUMIF(PARCELAMENTOS!$N:$N,">31/05/2028",PARCELAMENTOS!$Q:$Q) -> 10722.2 | I5: =SUMIF(PARCELAMENTOS!$N:$N,">30/06/2028",PARCELAMENTOS!$Q:$Q) -> 10722.2 | J5: =SUMIF(PARCELAMENTOS!$N:$N,">31/07/2028",PARCELAMENTOS!$Q:$Q) -> 10722.2 | K5: =SUMIF(PARCELAMENTOS!$N:$N,">31/08/2028",PARCELAMENTOS!$Q:$Q) -> 10722.2 | L5: =SUMIF(PARCELAMENTOS!$N:$N,">30/09/2028",PARCELAMENTOS!$Q:$Q) -> 10722.2 | M5: =SUMIF(PARCELAMENTOS!$N:$N,">31/10/2028",PARCELAMENTOS!$Q:$Q) -> 10722.2 | N5: =SUMIF(PARCELAMENTOS!$N:$N,">30/11/2028",PARCELAMENTOS!$Q:$Q) -> 10722.2
A6: 2029 | B6: =SUM(C6:N6) -> 79894.5 | C6: =SUMIF(PARCELAMENTOS!$N:$N,">30/12/2028",PARCELAMENTOS!$Q:$Q) -> 10722.2 | D6: =SUMIF(PARCELAMENTOS!$N:$N,">31/01/2029",PARCELAMENTOS!$Q:$Q) -> 10722.2 | E6: =SUMIF(PARCELAMENTOS!$N:$N,">28/02/2029",PARCELAMENTOS!$Q:$Q) -> 5845.01 | F6: =SUMIF(PARCELAMENTOS!$N:$N,">31/03/2029",PARCELAMENTOS!$Q:$Q) -> 5845.01 | G6: =SUMIF(PARCELAMENTOS!$N:$N,">30/04/2029",PARCELAMENTOS!$Q:$Q) -> 5845.01 | H6: =SUMIF(PARCELAMENTOS!$N:$N,">31/05/2029",PARCELAMENTOS!$Q:$Q) -> 5845.01 | I6: =SUMIF(PARCELAMENTOS!$N:$N,">30/06/2029",PARCELAMENTOS!$Q:$Q) -> 5845.01 | J6: =SUMIF(PARCELAMENTOS!$N:$N,">31/07/2029",PARCELAMENTOS!$Q:$Q) -> 5845.01 | K6: =SUMIF(PARCELAMENTOS!$N:$N,">31/08/2029",PARCELAMENTOS!$Q:$Q) -> 5845.01 | L6: =SUMIF(PARCELAMENTOS!$N:$N,">30/09/2029",PARCELAMENTOS!$Q:$Q) -> 5845.01 | M6: =SUMIF(PARCELAMENTOS!$N:$N,">31/10/2029",PARCELAMENTOS!$Q:$Q) -> 5845.01 | N6: =SUMIF(PARCELAMENTOS!$N:$N,">30/11/2029",PARCELAMENTOS!$Q:$Q) -> 5845.01
A7: 2030 | B7: =SUM(C7:N7) -> 61614.24 | C7: =SUMIF(PARCELAMENTOS!$N:$N,">30/12/2029",PARCELAMENTOS!$Q:$Q) -> 5134.52 | D7: =SUMIF(PARCELAMENTOS!$N:$N,">31/01/2030",PARCELAMENTOS!$Q:$Q) -> 5134.52 | E7: =SUMIF(PARCELAMENTOS!$N:$N,">28/02/2030",PARCELAMENTOS!$Q:$Q) -> 5134.52 | F7: =SUMIF(PARCELAMENTOS!$N:$N,">31/03/2030",PARCELAMENTOS!$Q:$Q) -> 5134.52 | G7: =SUMIF(PARCELAMENTOS!$N:$N,">30/04/2030",PARCELAMENTOS!$Q:$Q) -> 5134.52 | H7: =SUMIF(PARCELAMENTOS!$N:$N,">31/05/2030",PARCELAMENTOS!$Q:$Q) -> 5134.52 | I7: =SUMIF(PARCELAMENTOS!$N:$N,">30/06/2030",PARCELAMENTOS!$Q:$Q) -> 5134.52 | J7: =SUMIF(PARCELAMENTOS!$N:$N,">31/07/2030",PARCELAMENTOS!$Q:$Q) -> 5134.52 | K7: =SUMIF(PARCELAMENTOS!$N:$N,">31/08/2030",PARCELAMENTOS!$Q:$Q) -> 5134.52 | L7: =SUMIF(PARCELAMENTOS!$N:$N,">30/09/2030",PARCELAMENTOS!$Q:$Q) -> 5134.52 | M7: =SUMIF(PARCELAMENTOS!$N:$N,">31/10/2030",PARCELAMENTOS!$Q:$Q) -> 5134.52 | N7: =SUMIF(PARCELAMENTOS!$N:$N,">30/11/2030",PARCELAMENTOS!$Q:$Q) -> 5134.52
A8: 2031 | B8: =SUM(C8:N8) -> 61614.24 | C8: =SUMIF(PARCELAMENTOS!$N:$N,">30/12/2030",PARCELAMENTOS!$Q:$Q) -> 5134.52 | D8: =SUMIF(PARCELAMENTOS!$N:$N,">31/01/2031",PARCELAMENTOS!$Q:$Q) -> 5134.52 | E8: =SUMIF(PARCELAMENTOS!$N:$N,">28/02/2031",PARCELAMENTOS!$Q:$Q) -> 5134.52 | F8: =SUMIF(PARCELAMENTOS!$N:$N,">31/03/2031",PARCELAMENTOS!$Q:$Q) -> 5134.52 | G8: =SUMIF(PARCELAMENTOS!$N:$N,">30/04/2031",PARCELAMENTOS!$Q:$Q) -> 5134.52 | H8: =SUMIF(PARCELAMENTOS!$N:$N,">31/05/2031",PARCELAMENTOS!$Q:$Q) -> 5134.52 | I8: =SUMIF(PARCELAMENTOS!$N:$N,">30/06/2031",PARCELAMENTOS!$Q:$Q) -> 5134.52 | J8: =SUMIF(PARCELAMENTOS!$N:$N,">31/07/2031",PARCELAMENTOS!$Q:$Q) -> 5134.52 | K8: =SUMIF(PARCELAMENTOS!$N:$N,">31/08/2031",PARCELAMENTOS!$Q:$Q) -> 5134.52 | L8: =SUMIF(PARCELAMENTOS!$N:$N,">30/09/2031",PARCELAMENTOS!$Q:$Q) -> 5134.52 | M8: =SUMIF(PARCELAMENTOS!$N:$N,">31/10/2031",PARCELAMENTOS!$Q:$Q) -> 5134.52 | N8: =SUMIF(PARCELAMENTOS!$N:$N,">30/11/2031",PARCELAMENTOS!$Q:$Q) -> 5134.52
A9: 2032 | B9: =SUM(C9:N9) -> 61614.24 | C9: =SUMIF(PARCELAMENTOS!$N:$N,">30/12/2031",PARCELAMENTOS!$Q:$Q) -> 5134.52 | D9: =SUMIF(PARCELAMENTOS!$N:$N,">31/01/2032",PARCELAMENTOS!$Q:$Q) -> 5134.52 | E9: =SUMIF(PARCELAMENTOS!$N:$N,">28/02/2032",PARCELAMENTOS!$Q:$Q) -> 5134.52 | F9: =SUMIF(PARCELAMENTOS!$N:$N,">31/03/2032",PARCELAMENTOS!$Q:$Q) -> 5134.52 | G9: =SUMIF(PARCELAMENTOS!$N:$N,">30/04/2032",PARCELAMENTOS!$Q:$Q) -> 5134.52 | H9: =SUMIF(PARCELAMENTOS!$N:$N,">31/05/2032",PARCELAMENTOS!$Q:$Q) -> 5134.52 | I9: =SUMIF(PARCELAMENTOS!$N:$N,">30/06/2032",PARCELAMENTOS!$Q:$Q) -> 5134.52 | J9: =SUMIF(PARCELAMENTOS!$N:$N,">31/07/2032",PARCELAMENTOS!$Q:$Q) -> 5134.52 | K9: =SUMIF(PARCELAMENTOS!$N:$N,">31/08/2032",PARCELAMENTOS!$Q:$Q) -> 5134.52 | L9: =SUMIF(PARCELAMENTOS!$N:$N,">30/09/2032",PARCELAMENTOS!$Q:$Q) -> 5134.52 | M9: =SUMIF(PARCELAMENTOS!$N:$N,">31/10/2032",PARCELAMENTOS!$Q:$Q) -> 5134.52 | N9: =SUMIF(PARCELAMENTOS!$N:$N,">30/11/2032",PARCELAMENTOS!$Q:$Q) -> 5134.52
A10: 2033 | B10: =SUM(C10:N10) -> 51891.28 | C10: =SUMIF(PARCELAMENTOS!$N:$N,">30/12/2032",PARCELAMENTOS!$Q:$Q) -> 5134.52 | D10: =SUMIF(PARCELAMENTOS!$N:$N,">31/01/2033",PARCELAMENTOS!$Q:$Q) -> 5134.52 | E10: =SUMIF(PARCELAMENTOS!$N:$N,">28/02/2033",PARCELAMENTOS!$Q:$Q) -> 5134.52 | F10: =SUMIF(PARCELAMENTOS!$N:$N,">31/03/2033",PARCELAMENTOS!$Q:$Q) -> 5134.52 | G10: =SUMIF(PARCELAMENTOS!$N:$N,">30/04/2033",PARCELAMENTOS!$Q:$Q) -> 5134.52 | H10: =SUMIF(PARCELAMENTOS!$N:$N,">31/05/2033",PARCELAMENTOS!$Q:$Q) -> 5134.52 | I10: =SUMIF(PARCELAMENTOS!$N:$N,">30/06/2033",PARCELAMENTOS!$Q:$Q) -> 5134.52 | J10: =SUMIF(PARCELAMENTOS!$N:$N,">31/07/2033",PARCELAMENTOS!$Q:$Q) -> 5134.52 | K10: =SUMIF(PARCELAMENTOS!$N:$N,">31/08/2033",PARCELAMENTOS!$Q:$Q) -> 5134.52 | L10: =SUMIF(PARCELAMENTOS!$N:$N,">30/09/2033",PARCELAMENTOS!$Q:$Q) -> 2840.3 | M10: =SUMIF(PARCELAMENTOS!$N:$N,">31/10/2033",PARCELAMENTOS!$Q:$Q) -> 2840.3 | N10: =SUMIF(PARCELAMENTOS!$N:$N,">30/11/2033",PARCELAMENTOS!$Q:$Q) -> 0
A12: 2025 | B12: =SUM(C12:N12) -> -5867.2 | D12: =D2-C2 -> 0 | E12: =E2-D2 -> 0 | F12: =F2-E2 -> 0 | G12: =G2-F2 -> 0 | H12: =H2-G2 -> 0 | I12: =I2-H2 -> 0 | J12: =J2-I2 -> -1876.85 | K12: =K2-J2 -> -1462.34 | ... N12: =N2-M2 -> -403.2
A13: 2026 | B13: =SUM(C13:N13) -> -19786.56 | C13: =C3-N2 -> -247.46 | D13: =D3-C3 -> -3528.54 | E13: =E3-D3 -> 0 | F13: =F3-E3 -> -750 | G13: =G3-F3 -> 0 | H13: =H3-G3 -> 0 | I13: =I3-H3 -> -5363.3 | J13: =J3-I3 -> 0 | K13: =K3-J3 -> -9897.26 | ... N13: =N3-M3 -> 0
A14: 2027 | B14: =SUM(C14:N14) -> -6240.01 | C14: =C4-N3 -> 0 | D14: =D4-C4 -> 0 | E14: =E4-D4 -> 0 | F14: =F4-E4 -> -369.97 | G14: =G4-F4 -> 0 | H14: =H4-G4 -> 0 | I14: =I4-H4 -> 0 | J14: =J4-I4 -> -5622.58 | K14: =K4-J4 -> 0 | ... N14: =N4-M4 -> 0
A15: 2028 | B15: =SUM(C15:N15) -> -9601.34 | C15: =C5-N4 -> -4601.34 | D15: =D5-C5 -> 0 | E15: =E5-D5 -> 0 | F15: =F5-E5 -> 0 | G15: =G5-F5 -> -5000 | H15: =H5-G5 -> 0 | I15: =I5-H5 -> 0 | J15: =J5-I5 -> 0 | K15: =K5-J5 -> 0 | ... N15: =N5-M5 -> 0
A16: 2029 | B16: =SUM(C16:N16) -> -4877.19 | C16: =C6-N5 -> 0 | D16: =D6-C6 -> 0 | E16: =E6-D6 -> -4877.19 | F16: =F6-E6 -> 0 | G16: =G6-F6 -> 0 | H16: =H6-G6 -> 0 | I16: =I6-H6 -> 0 | J16: =J6-I6 -> 0 | K16: =K6-J6 -> 0 | ... N16: =N6-M6 -> 0
A17: 2030 | B17: =SUM(C17:N17) -> -710.49 | C17: =C7-N6 -> -710.49 | D17: =D7-C7 -> 0 | E17: =E7-D7 -> 0 | F17: =F7-E7 -> 0 | G17: =G7-F7 -> 0 | H17: =H7-G7 -> 0 | I17: =I7-H7 -> 0 | J17: =J7-I7 -> 0 | K17: =K7-J7 -> 0 | ... N17: =N7-M7 -> 0
A18: 2031 | B18: =SUM(C18:N18) -> 0 | C18: =C8-N7 -> 0 | D18: =D8-C8 -> 0 | E18: =E8-D8 -> 0 | F18: =F8-E8 -> 0 | G18: =G8-F8 -> 0 | H18: =H8-G8 -> 0 | I18: =I8-H8 -> 0 | J18: =J8-I8 -> 0 | K18: =K8-J8 -> 0 | ... N18: =N8-M8 -> 0
A19: 2032 | B19: =SUM(C19:N19) -> 0 | C19: =C9-N8 -> 0 | D19: =D9-C9 -> 0 | E19: =E9-D9 -> 0 | F19: =F9-E9 -> 0 | G19: =G9-F9 -> 0 | H19: =H9-G9 -> 0 | I19: =I9-H9 -> 0 | J19: =J9-I9 -> 0 | K19: =K9-J9 -> 0 | ... N19: =N9-M9 -> 0
A20: 2033 | B20: =SUM(C20:N20) -> -5134.52 | C20: =C10-N9 -> 0 | D20: =D10-C10 -> 0 | E20: =E10-D10 -> 0 | F20: =F10-E10 -> 0 | G20: =G10-F10 -> 0 | H20: =H10-G10 -> 0 | I20: =I10-H10 -> 0 | J20: =J10-I10 -> 0 | K20: =K10-J10 -> 0 | ... N20: =N10-M10 -> -2840.3

Sheet DAS Parc
A1: Cód. Interno | B1: Data | C1: Entidade | D1: Descrição | E1: Valor | F1: Principal | G1: Correção
D2: Total pago | E2: =SUM(E3:E151) -> 80788.61 | F2: =SUM(F3:F151) -> 65894.27 | G2: =SUM(G3:G151) -> 14894.34
B3: 44454 | C3: Simples Nacional | D3: Despesas Parcelamento Imposto MBR 01/145 Simples | E3: 954.43 | F3: 954.43 | G3: =E3-F3 -> 0
B4: 44498 | C4: Simples Nacional | D4: Despesas Parcelamento Imposto MBR 02/145 Simples | E4: 963.98 | F4: 954.43 | G4: =E4-F4 -> 9.55
B5: 44530 | C5: Simples Nacional | D5: Despesas Parcelamento Imposto MBR 03/145 Simples | E5: 968.66 | F5: 954.43 | G5: =E5-F5 -> 14.23
B6: 44552 | C6: Simples Nacional | D6: Despesas Parcelamento Imposto MBR 04/145 Simples | E6: 974.29 | F6: 954.43 | G6: =E6-F6 -> 19.86
A7: 2933 | B7: 31/01/2022 | C7: Simples Nacional | D7: Despesas Parcelamento Imposto MBR 05/145 Simples Nacional | E7: 981.64 | F7: 954.43 | G7: =E7-F7 -> 27.21
A8: 2934 | B8: 25/02/2022 | C8: Simples Nacional | D8: Despesas Parcelamento Imposto MBR 06/145 Simples Nacional | E8: 988.6 | F8: 954.43 | G8: =E8-F8 -> 34.17
A9: 4781 | B9: 31/03/2022 | C9: Simples Nacional | D9: Despesas Parcelamento Imposto MBR 07/145 Simples Nacional | E9: 995.86 | F9: 954.43 | G9: =E9-F9 -> 41.43
A10: 2936 | B10: 29/04/2022 | C10: Simples Nacional | D10: Despesas Parcelamento Imposto MBR 08/145 Simples Nacional | E10: 1004.73 | F10: 954.43 | G10: =E10-F10 -> 50.3
A11: 2937 | B11: 31/05/2022 | C11: Simples Nacional | D11: Despesas Parcelamento Imposto MBR 09/145 Simples Nacional | E11: 1012.66 | F11: 954.43 | G11: =E11-F11 -> 58.23
A12: 2938 | B12: 27/06/2022 | C12: Simples Nacional | D12: Despesas Parcelamento Imposto MBR 10/145 Simples Nacional | E12: 929.52 | F12: 954.43 | G12: =E12-F12 -> -24.91
A13: 2939 | B13: 25/07/2022 | C13: Simples Nacional | D13: Despesas Parcelamento Imposto MBR 11/145 Simples Nacional | E13: 1032.22 | F13: 954.43 | G13: =E13-F13 -> 77.79
A14: 5616 | B14: 25/07/2022 | C14: Simples Nacional | D14: Despesas Parcelamento Imposto MBR Diferença 11/145 Simples Nacional | E14: 93.81 | F14: 93.81 | G14: =E14-F14 -> 0
A15: 2940 | B15: 31/08/2022 | C15: Simples Nacional | D15: Despesas Parcelamento Imposto MBR 12/145 Simples Nacional | E15: 1042.05 | F15: 954.43 | G15: =E15-F15 -> 87.62
A16: 2941 | B16: 29/09/2022 | C16: Simples Nacional | D16: Despesas Parcelamento Imposto MBR 13/145 Simples Nacional | E16: 1763.89 | F16: 1598.45 | G16: =E16-F16 -> 165.44
A17: 5228 | B17: 31/10/2022 | C17: Simples Nacional | D17: Despesas Parcelamento Imposto MBR 14/145 Simples Nacional | E17: 1780.96 | F17: 1598.45 | G17: =E17-F17 -> 182.51
A18: 5229 | B18: 30/11/2022 | C18: Simples Nacional | D18: Despesas Parcelamento Imposto MBR 15/145 Simples Nacional | E18: 1797.27 | F18: 1598.45 | G18: =E18-F18 -> 198.82
... A43: 14767 | B43: 27/12/2024 | C43: Simples Nacional | D43: Despesas Parcelamento Imposto MBR 40/145 Simples Nacional | E43: 2179.29 | F43: 1598.45 | G43: =E43-F43 -> 580.84
B44: 45693 | C44: Simples Nacional | D44: Despesas Parcelamento Imposto MBR 41/145 Simples Nacional | E44: 2210.3 | F44: 1598.45 | G44: =E44-F44 -> 611.85
B45: 45716 | C45: Simples Nacional | D45: Despesas Parcelamento Imposto MBR 42/145 Simples Nacional | E45: 2210.3 | F45: 1598.45 | G45: =E45-F45 -> 611.85
B46: 45747 | C46: Simples Nacional | D46: Despesas Parcelamento Imposto MBR 43/145 Simples Nacional | E46: 2226.12 | F46: 1598.45 | G46: =E46-F46 -> 627.67
A47: 25286 | B47: 28/04/2025 | C47: Simples Nacional | D47: Despesas Parcelamento Imposto MBR 44/145 Simples Nacional | E47: 2241.47 | F47: 1598.45 | G47: =E47-F47 -> 643.02
B48: 45803 | C48: Simples Nacional | D48: Despesas Parcelamento Imposto MBR 45/145 Simples Nacional | E48: 2258.41 | F48: 1598.45 | G48: =E48-F48 -> 659.96
B49: 45841 | C49: Simples Nacional | D49: Despesas Parcelamento Imposto MBR 46/145 Simples Nacional | E49: 2294.22 | F49: 1598.45 | G49: =E49-F49 -> 695.77

Sheet Consórcios
A1: Cota | B1: Total | C1: Período | D1: Vr. Pago
A2: Consórcio Bradesco Grupo 10447 cota 54 | B2: =F2+D2+H2 -> 20387.33 | C2: 09/23 a 05/25 | D2: 13208.25 | E2: 09/22 a 04/23 | F2: =8*593.8 -> 4750.4 | G2: 05/23 a 08/23 | H2: =605.67+612.96+609.3+600.75 -> 2428.68
A4: Consórcio Bradesco Grupo 10010 cota 167 | B4: =D4+F4+H4 -> 3812.01 | C4: 03/23 a 08/23 | D4: =752.81+752.81+767.86+776.88+761.65 -> 3812.01
A5: Consórcio Bradesco Grupo 10051 cota 186 | B5: =D5+F5+H5 -> 3754.47 | C5: 03/23 a 08/23 | D5: =750.17+765.13+756.27+741.45+741.45 -> 3754.47
A6: Consórcio Bradesco Grupo 10069 cota 175 | B6: =D6+F6+H6 -> 3754.47 | C6: 03/23 a 08/23 | D6: =750.17+765.13+756.27+741.45+741.45 -> 3754.47
A7: Consórcio Massey Grupo 0366 cota 0804 | B7: =D7+F7+H7 -> 79635.02 | C7: 01/24 a 12/24 | D7: 23932.4 | E7: 45778 | F7: 55702.62
A8: Consórcio Massey Grupo 0367 cota 0202 | B8: =D8+F8+H8 -> 80221.58 | C8: 01/24 a 12/24 | D8: 24108.7 | E8: 45778 | F8: 56112.88
